<?xml version="1.0" ?><mujoco model="base">	
  	<compiler angle="radian" meshdir="meshes/"/>	
  	<option impratio="20" cone="elliptic"/>	
  	<size nconmax="5000" njmax="5000"/>	
  	<visual>		
      		<map znear="0.001"/>		
  	</visual>	

  	<asset>		
  		<texture builtin="flat" height="256" rgb1="1 1 1." rgb2=".2 .3 .4" type="skybox" width="256"/>		
        		<texture builtin="checker" height="512" name="texplane" rgb1=".2 .3 .4" rgb2=".1 0.15 0.2" type="2d" width="512"/>		
        		<material name="floorplane" reflectance="0.5" texrepeat="1 1" texture="texplane" texuniform="true"/>		
    		<mesh file="D:\Documents\USC\Furniture\furniture\furniture-test\furniture\furniture\env\models\assets\robots\sawyer\meshes/pedestal.stl" name="pedestal"/>		
        		<mesh file="D:\Documents\USC\Furniture\furniture\furniture-test\furniture\furniture\env\models\assets\robots\sawyer\meshes/base.stl" name="base"/>		
        		<mesh file="D:\Documents\USC\Furniture\furniture\furniture-test\furniture\furniture\env\models\assets\robots\sawyer\meshes/l0.stl" name="l0"/>		
        		<mesh file="D:\Documents\USC\Furniture\furniture\furniture-test\furniture\furniture\env\models\assets\robots\sawyer\meshes/head.stl" name="head"/>		
        		<mesh file="D:\Documents\USC\Furniture\furniture\furniture-test\furniture\furniture\env\models\assets\robots\sawyer\meshes/l1.stl" name="l1"/>		
        		<mesh file="D:\Documents\USC\Furniture\furniture\furniture-test\furniture\furniture\env\models\assets\robots\sawyer\meshes/l2.stl" name="l2"/>		
        		<mesh file="D:\Documents\USC\Furniture\furniture\furniture-test\furniture\furniture\env\models\assets\robots\sawyer\meshes/l3.stl" name="l3"/>		
        		<mesh file="D:\Documents\USC\Furniture\furniture\furniture-test\furniture\furniture\env\models\assets\robots\sawyer\meshes/l4.stl" name="l4"/>		
        		<mesh file="D:\Documents\USC\Furniture\furniture\furniture-test\furniture\furniture\env\models\assets\robots\sawyer\meshes/l5.stl" name="l5"/>		
        		<mesh file="D:\Documents\USC\Furniture\furniture\furniture-test\furniture\furniture\env\models\assets\robots\sawyer\meshes/l6.stl" name="l6"/>		
    		<mesh name="electric_gripper_base" file="D:\Documents\USC\Furniture\furniture\furniture-test\furniture\furniture\env\models\assets\grippers\meshes/two_finger_gripper/electric_gripper_base.STL"/>		
        		<mesh name="standard_narrow" file="D:\Documents\USC\Furniture\furniture\furniture-test\furniture\furniture\env\models\assets\grippers\meshes/two_finger_gripper/standard_narrow.STL"/>		
        		<mesh name="half_round_tip" file="D:\Documents\USC\Furniture\furniture\furniture-test\furniture\furniture\env\models\assets\grippers\meshes/two_finger_gripper/half_round_tip.STL"/>		
    		<texture file="D:\Documents\USC\Furniture\furniture\furniture-test\furniture\furniture\env\models\assets\objects\../textures/light-wood.png" name="tex-light-wood" type="2d"/>		
    		<material name="light-wood" reflectance="0.5" texrepeat="20 20" texture="tex-light-wood" texuniform="true"/>		
  	</asset>	

  	<actuator>		
  		<velocity ctrllimited="true" ctrlrange="-1.74 1.74" joint="right_j0" kv="8.0" name="vel_right_j0"/>		
        		<velocity ctrllimited="true" ctrlrange="-1.328 1.328" joint="right_j1" kv="7.0" name="vel_right_j1"/>		
        		<velocity ctrllimited="true" ctrlrange="-1.957 1.957" joint="right_j2" kv="6.0" name="vel_right_j2"/>		
        		<velocity ctrllimited="true" ctrlrange="-1.957 1.957" joint="right_j3" kv="4.0" name="vel_right_j3"/>		
        		<velocity ctrllimited="true" ctrlrange="-3.485 3.485" joint="right_j4" kv="2.0" name="vel_right_j4"/>		
        		<velocity ctrllimited="true" ctrlrange="-3.485 3.485" joint="right_j5" kv="0.5" name="vel_right_j5"/>		
        		<velocity ctrllimited="true" ctrlrange="-4.545 4.545" joint="right_j6" kv="0.1" name="vel_right_j6"/>		
    		<position ctrllimited="true" ctrlrange="-0.020833 0.0115" joint="r_gripper_r_finger_joint" kp="10000" name="gripper_r_gripper_r_finger_joint" forcelimited="true" forcerange="-20 20"/>		
        		<position ctrllimited="true" ctrlrange="-0.0115 0.020833" joint="r_gripper_l_finger_joint" kp="10000" name="gripper_r_gripper_l_finger_joint" forcelimited="true" forcerange="-20 20"/>		
    	</actuator>	

  	<worldbody>		
  		<geom condim="3" rgba="0.7 0.7 0.7 1" name="FLOOR" pos="0 0 0" size="0.75 0.5 0.0625" type="plane" friction="2.0 0.005 0.0001"/>		

        		<body name="VR_R" pos="0.2 -0.2 0.3">			
            			<site rgba="0.7 0.2 0.2 1" name="VR_R_x" pos="0.05 0 0" size="0.05 0.002 0.002" type="box"/>			
            			<site rgba="0.2 0.7 0.2 1" name="VR_R_y" pos="0 0.05 0" size="0.002 0.05 0.002" type="box"/>			
            			<site rgba="0.2 0.2 0.7 1" name="VR_R_z" pos="0 0 0.05" size="0.002 0.002 0.05" type="box"/>			
        		</body>		

        		<light diffuse=".8 .8 .8" dir=".5 -.3 -.8" directional="true" pos="0 0 2.0" specular="0.3 0.3 0.3" castshadow="true"/>		

        
        
        
        		<camera mode="fixed" name="frontview" pos="0 -1.2 0.9" quat="0.86 0.51 0. 0." fovy="60"/>		
        		<camera mode="fixed" name="sideview" pos="-2.5 0. 0.5" quat="0.5468 0.4482 -0.4482 -0.5468"/>		
    		<body name="base" pos="0.0 0.65 0.21300000000000008" quat="1 0 0 -1">			
            			<inertial diaginertia="0 0 0" mass="0" pos="0 0 0"/>			
            			<body name="controller_box" pos="0 0 0">				
                				<inertial diaginertia="1.71363 1.27988 0.809981" mass="46.64" pos="-0.325 0 -0.38"/>				
                				<geom name="controller_box_visual" conaffinity="0" contype="0" pos="-0.325 0 -0.38" size="0.11 0.2 0.265" type="box"/>				
            			</body>			
            			<body name="pedestal_feet" pos="0 0 0">				
                				<inertial diaginertia="8.16095 9.59375 15.0785" mass="167.09" pos="-0.1225 0 -0.758"/>				
                				<geom name="pedestal_feet_visual" conaffinity="0" contype="0" pos="-0.1225 0 -0.758" size="0.385 0.35 0.155" type="box"/>				
            			</body>			
            			<body name="torso" pos="0 0 0">				
                				<inertial diaginertia="1e-08 1e-08 1e-08" mass="0.0001" pos="0 0 0"/>				
                				<geom name="torso_visual" conaffinity="0" contype="0" group="1" rgba="0.2 0.2 0.2 1" size="0.05 0.05 0.05" type="box"/>				
            			</body>			
            			<body name="pedestal" pos="0 0 0">				
                				<inertial diaginertia="6.0869 5.81635 4.20915" mass="60.864" pos="0 0 0" quat="0.659267 -0.259505 -0.260945 0.655692"/>				
                				<geom name="pedestal_visual" conaffinity="0" contype="0" group="1" mesh="pedestal" pos="0.26 0.345 -0.91488" quat="0.5 0.5 -0.5 -0.5" rgba="0.2 0.2 0.2 1" type="mesh"/>				
                				<geom name="pedestal_collision" pos="-0.02 0 -0.29" rgba="0.2 0.2 0.2 1" size="0.18 0.31" type="cylinder"/>				
            			</body>			
            			<body name="right_arm_base_link" pos="0 0 0">				
                				<inertial diaginertia="0.00740351 0.00681776 0.00672942" mass="2.0687" pos="-0.0006241 -2.8025e-05 0.065404" quat="-0.209285 0.674441 0.227335 0.670558"/>				
                				<geom name="right_arm_base_link_visual" conaffinity="0" contype="0" group="1" mesh="base" rgba="0.5 0.1 0.1 1" type="mesh"/>				
                				<geom name="right_arm_base_link_collision" pos="0 0 0.12" rgba="0.5 0.1 0.1 1" size="0.08 0.12" type="cylinder"/>				
                				<body name="right_l0" pos="0 0 0.08">					
                    					<inertial diaginertia="0.0651588 0.0510944 0.0186218" mass="5.3213" pos="0.024366 0.010969 0.14363" quat="0.894823 0.00899958 -0.170275 0.412573"/>					
                    					<joint axis="0 0 1" limited="true" name="right_j0" pos="0 0 0" range="-3.0503 3.0503"/>					
                    					<geom name="right_l0_visual" conaffinity="0" contype="0" group="1" mesh="l0" rgba="0.5 0.1 0.1 1" type="mesh"/>					
                    					<geom name="right_l0_collision" pos="0.08 0 0.23" rgba="0.5 0.1 0.1 1" size="0.07"/>					
                    					<body name="head" pos="0 0 0.2965">						
                        						<inertial diaginertia="0.0118334 0.00827089 0.00496574" mass="1.5795" pos="0.0053207 -2.6549e-05 0.1021" quat="0.999993 7.08405e-05 -0.00359857 -0.000626247"/>						
                            
                            						<geom name="head_visual" conaffinity="0" contype="0" group="1" mesh="head" rgba="0.5 0.1 0.1 1" type="mesh"/>						
                            						<geom name="head_collision" pos="0 0 0.08" rgba="0.5 0.1 0.1 1" size="0.018"/>						
                            						<body name="screen" pos="0.03 0 0.105" quat="0.5 0.5 0.5 0.5">							
                                							<inertial diaginertia="1e-08 1e-08 1e-08" mass="0.0001" pos="0 0 0"/>							
                                							<geom name="screen_visual" conaffinity="0" contype="0" group="1" rgba="0.2 0.2 0.2 1" size="0.12 0.07 0.001" type="box"/>							
                                							<geom name="screen_collision" rgba="0.2 0.2 0.2 1" size="0.001"/>							
                            						</body>						
                            						<body name="head_camera" pos="0.0228027 0 0.216572" quat="0.342813 -0.618449 0.618449 -0.342813">							
                                							<inertial diaginertia="0 0 0" mass="0" pos="0.0228027 0 0.216572" quat="0.342813 -0.618449 0.618449 -0.342813"/>							
                            						</body>						
                        					</body>					
                        					<body name="right_torso_itb" pos="-0.055 0 0.22" quat="0.707107 0 -0.707107 0">						
                            						<inertial diaginertia="1e-08 1e-08 1e-08" mass="0.0001" pos="0 0 0"/>						
                        					</body>					
                        					<body name="right_l1" pos="0.081 0.05 0.237" quat="0.5 -0.5 0.5 0.5">						
                            						<inertial diaginertia="0.0224339 0.0221624 0.0097097" mass="4.505" pos="-0.0030849 -0.026811 0.092521" quat="0.424888 0.891987 0.132364 -0.0794296"/>						
                            						<joint axis="0 0 1" limited="true" name="right_j1" pos="0 0 0" range="-3.8095 2.2736"/>						
                            						<geom name="right_l1_visual" conaffinity="0" contype="0" group="1" mesh="l1" rgba="0.5 0.1 0.1 1" type="mesh"/>						
                            						<geom name="right_l1_collision" pos="0 0 0.1225" rgba="0.5 0.1 0.1 1" size="0.07"/>						
                            						<body name="right_l2" pos="0 -0.14 0.1425" quat="0.707107 0.707107 0 0">							
                                							<inertial diaginertia="0.0257928 0.025506 0.00292515" mass="1.745" pos="-0.00016044 -0.014967 0.13582" quat="0.707831 -0.0524761 0.0516007 0.702537"/>							
                                							<joint axis="0 0 1" limited="true" name="right_j2" pos="0 0 0" range="-3.0426 3.0426"/>							
                                							<geom name="right_l2_visual" conaffinity="0" contype="0" group="1" mesh="l2" rgba="0.5 0.1 0.1 1" type="mesh"/>							
                                							<geom name="right_l2_collision" pos="0 0 0.08" rgba="0.5 0.1 0.1 1" size="0.06 0.17" type="cylinder"/>							
                                							<body name="right_l3" pos="0 -0.042 0.26" quat="0.707107 -0.707107 0 0">								
                                    								<inertial diaginertia="0.0102404 0.0096997 0.00369622" mass="2.5097" pos="-0.0048135 -0.0281 -0.084154" quat="0.902999 0.385391 -0.0880901 0.168247"/>								
                                    								<joint axis="0 0 1" limited="true" name="right_j3" pos="0 0 0" range="-3.0439 3.0439"/>								
                                    								<geom name="right_l3_visual" conaffinity="0" contype="0" group="1" mesh="l3" rgba="0.5 0.1 0.1 1" type="mesh"/>								
                                    								<geom name="right_l3_collision" pos="0 -0.01 -0.12" rgba="0.5 0.1 0.1 1" size="0.06"/>								
                                    								<body name="right_l4" pos="0 -0.125 -0.1265" quat="0.707107 0.707107 0 0">									
                                        									<inertial diaginertia="0.0136549 0.0135493 0.00127353" mass="1.1136" pos="-0.0018844 0.0069001 0.1341" quat="0.803612 0.031257 -0.0298334 0.593582"/>									
                                        									<joint axis="0 0 1" limited="true" name="right_j4" pos="0 0 0" range="-2.9761 2.9761"/>									
                                        									<geom name="right_l4_visual" conaffinity="0" contype="0" group="1" mesh="l4" rgba="0.5 0.1 0.1 1" type="mesh"/>									
                                        									<geom name="right_l4_collision" pos="0 0 0.11" rgba="0.5 0.1 0.1 1" size="0.045 0.15" type="cylinder"/>									
                                        									<body name="right_arm_itb" pos="-0.055 0 0.075" quat="0.707107 0 -0.707107 0">										
                                            										<inertial diaginertia="1e-08 1e-08 1e-08" mass="0.0001" pos="0 0 0"/>										
                                        									</body>									
                                        									<body name="right_l5" pos="0 0.031 0.275" quat="0.707107 -0.707107 0 0">										
                                            										<inertial diaginertia="0.00474131 0.00422857 0.00190672" mass="1.5625" pos="0.0061133 -0.023697 0.076416" quat="0.404076 0.9135 0.0473125 0.00158335"/>										
                                            										<joint axis="0 0 1" limited="true" name="right_j5" pos="0 0 0" range="-2.9761 2.9761" damping="0.2"/>										
                                            										<geom name="right_l5_visual" conaffinity="0" contype="0" group="1" mesh="l5" rgba="0.5 0.1 0.1 1" type="mesh"/>										
                                            										<geom name="right_l5_collision" pos="0 0 0.1" rgba="0.5 0.1 0.1 1" size="0.06"/>										
                                            										<body name="right_hand_camera" pos="0.039552 -0.033 0.0695" quat="0.707107 0 0.707107 0">											
                                                											<inertial diaginertia="0 0 0" mass="0" pos="0.039552 -0.033 0.0695" quat="0.707107 0 0.707107 0"/>											
                                            										</body>										
                                            										<body name="right_wrist" pos="0 0 0.10541" quat="0.707107 0.707107 0 0">											
                                                											<inertial diaginertia="0 0 0" mass="0" pos="0 0 0.10541" quat="0.707107 0.707107 0 0"/>											
                                            										</body>										
                                            										<body name="right_l6" pos="0 -0.11 0.1053" quat="0.0616248 0.06163 -0.704416 0.704416">											
                                                											<camera name="wrist_cam" pos="0 0.1 0" euler="-2.7 0 0"/>											
                                                											<inertial diaginertia="0.000360258 0.000311068 0.000214974" mass="0.3292" pos="-8.0726e-06 0.0085838 -0.0049566" quat="0.479044 0.515636 -0.513069 0.491322"/>											
                                                											<joint axis="0 0 1" limited="true" name="right_j6" pos="0 0 0" range="-4.7124 4.7124" damping="0.1"/>											
                                                											<geom name="right_l6_visual" conaffinity="0" contype="0" group="1" mesh="l6" rgba="0.5 0.1 0.1 1" type="mesh"/>											
                                                											<geom name="right_l6_collision" pos="0 0.015 -0.01" rgba="0.5 0.1 0.1 1" size="0.055 0.025" type="cylinder"/>											
                                                											<body name="right_hand" pos="0 0 0.0245" quat="0.707105 0 0 0.707108">												
                                                    
                                                    												<site name="ee" pos="0 0 0" size="0.01 0.01 0.01" rgba="0 0 1 1" type="sphere" group="1"/>												
                                                    												<site name="ee_x" pos="0 0 0" size="0.005 .1" quat="0.707105 0.707108 0 0 " rgba="1 0 0 1" type="cylinder" group="1"/>												
                                                    												<site name="ee_z" pos="0 0 0" size="0.005 .1" quat="0.707105 0 0 0.707108" rgba="0 0 1 1" type="cylinder" group="1"/>												
                                                    												<site name="ee_y" pos="0 0 0" size="0.005 .1" quat="0.707105 0 0.707108 0 " rgba="0 1 0 1" type="cylinder" group="1"/>												
                                                    
                                                												<body name="right_gripper_base" pos="0 0 0.025">													
            													<site name="ft_frame" pos="0 0 0" size="0.01 0.01 0.01" rgba="1 0 0 1" type="sphere" group="1"/>													
            													<inertial pos="0 0 0" quat="-0.5 0.5 0.5 0.5" mass="0.3" diaginertia="3e-08 2e-08 2e-08"/>													
            													<geom name="right_gripper_base_visual" quat="0 0 0.707107 0.707107" type="mesh" contype="0" conaffinity="0" group="1" mesh="electric_gripper_base"/>													
            													<geom name="right_gripper_base_collision" size="0.029 0.05" quat="0 0 0.707107 0.707107" type="cylinder"/>													
            													<body name="right_gripper" pos="0 0 0.095">														
                														<inertial pos="0 0 0" mass="0.0001" diaginertia="0 0 0"/>														
                
                														<site name="grip_site" pos="0 0 -0.03" size="0.01 0.01 0.01" rgba="0 0 0 0" type="sphere" group="1"/>														
                
                														<site name="griptip_site" pos="0 0 0" size="0.01 0.01 0.01" rgba="1 0 0 1" type="sphere" group="1"/>														
                														<site name="lgriptip_site" pos="0 0.02 0" size="0.01 0.01 0.01" rgba="1 0 0 1" type="sphere" group="1"/>														
                														<site name="rgriptip_site" pos="0 -0.02 0" size="0.01 0.01 0.01" rgba="1 0 0 1" type="sphere" group="1"/>														

                
                														<site name="grip_site_cylinder" pos="0 0 0" size="0.005 10" rgba="0 0 0 0" type="cylinder" group="1"/>														
                
                														<camera mode="fixed" name="eye_in_hand" pos="0 0 0" quat="0 -1 1 0" fovy="75"/>														
            													</body>													
            
            													<body name="r_gripper_l_finger" pos="0 0.01 0.02">														
                														<inertial pos="0 0 0" quat="0 0 0 -1" mass="0.02" diaginertia="0.01 0.01 0.01"/>														
                														<joint name="r_gripper_l_finger_joint" pos="0 0 0" axis="0 1 0" type="slide" limited="true" range="-0.0115 0.020833" damping="100"/>														
                														<geom name="r_gripper_l_finger_visual" quat="0 0 0 -1" type="mesh" contype="0" conaffinity="0" group="1" mesh="standard_narrow"/>														
                														<geom size="0.005 0.00675 0.0375" pos="0 0.01725 0.04" quat="0 0 0 -1" type="box" conaffinity="1" contype="0" name="l_finger_g0" friction="0 0 0"/>														
                														<geom size="0.005 0.025 0.0085" pos="-0.005 -0.003 0.0083" quat="0 0 0 -1" type="box" conaffinity="1" contype="0" name="l_finger_g1" friction="0 0 0"/>														

                														<body name="r_gripper_l_finger_tip" pos="0 0.01725 0.075">															
                    															<inertial pos="0 0 0" quat="0 0 0 1" mass="0.01" diaginertia="0.01 0.01 0.01"/>															
                    															<geom name="r_gripper_l_finger_tip_visual" quat="0 0 0 1" type="mesh" contype="0" conaffinity="0" group="1" mesh="half_round_tip"/>															
                
                															<geom size="0.004 0.004 0.0185" pos="0 -0.0045 -0.015" quat="0 0 0 1" type="box" conaffinity="1" contype="0" name="l_fingertip_g0" friction="2 10 0.5"/>															

                														</body>														
            													</body>													
            													<body name="r_gripper_r_finger" pos="0 -0.01 0.02">														
                														<inertial pos="0 0 0" mass="0.02" diaginertia="0.01 0.01 0.01"/>														
                														<joint name="r_gripper_r_finger_joint" pos="0 0 0" axis="0 1 0" type="slide" limited="true" range="-0.020833 0.0115" damping="100"/>														
                														<geom name="r_gripper_r_finger_visual" type="mesh" contype="0" conaffinity="0" group="1" mesh="standard_narrow"/>														
                														<geom size="0.005 0.00675 0.0375" pos="0 -0.01725 0.04" type="box" conaffinity="1" contype="0" name="r_finger_g0" friction="0 0 0"/>														
                														<geom size="0.005 0.025 0.0085" pos="0.005 0.003 0.0083" type="box" conaffinity="1" contype="0" name="r_finger_g1" friction="0 0 0"/>														
                														<body name="r_gripper_r_finger_tip" pos="0 -0.01725 0.075">															
                    															<inertial pos="0 0 0" mass="0.01" diaginertia="0.01 0.01 0.01"/>															
                    															<geom name="r_gripper_r_finger_tip_visual" type="mesh" contype="0" conaffinity="0" group="1" mesh="half_round_tip"/>															
                    															<geom size="0.004 0.004 0.0185" pos="0 0.0045 -0.015" type="box" conaffinity="1" contype="0" name="r_fingertip_g0" friction="2 10 0.5"/>															
                														</body>														
            													</body>													
        												</body>												
    											</body>											
                                            										</body>										
                                        									</body>									
                                        									<body name="right_l4_2" pos="0 0 0">										
                                            										<inertial diaginertia="1e-08 1e-08 1e-08" mass="1e-08" pos="1e-08 1e-08 1e-08" quat="0.820473 0.339851 -0.17592 0.424708"/>										
                                            										<geom name="right_l4_2_collision" pos="0 0.01 0.26" size="0.06"/>										
                                        									</body>									
                                    								</body>								
                                							</body>							
                                							<body name="right_l2_2" pos="0 0 0">								
                                    								<inertial diaginertia="1e-08 1e-08 1e-08" mass="1e-08" pos="1e-08 1e-08 1e-08" quat="0.820473 0.339851 -0.17592 0.424708"/>								
                                    								<geom name="right_l2_2_collision" pos="0 0 0.26" size="0.06"/>								
                                							</body>							
                            						</body>						
                            						<body name="right_l1_2" pos="0 0 0">							
                                							<inertial diaginertia="1e-08 1e-08 1e-08" mass="1e-08" pos="1e-08 1e-08 1e-08" quat="0.820473 0.339851 -0.17592 0.424708"/>							
                                							<geom name="right_l1_2_collision" pos="0 0 0.035" size="0.07 0.07" type="cylinder"/>							
                            						</body>						
                        					</body>					
                    				</body>				
                			</body>			
            		</body>		
        		<body pos="0.0 0.0 0.03" quat="1 0 0 0" name="1_block_l">			
      			<geom density="100" material="light-wood" name="1_block_l-0" pos="0 0 0" rgba="0.82 0.71 0.55 1" size="0.05 0.02 0.03" solref="0.001 1" type="box" friction="1 10 0.5"/>			
      			<site name="1_block_l_ltgt_site0" pos="0 -0.02 0.02" size="0.01 0.01 0.01" rgba="1 0 0 1" type="sphere" group="1"/>			
      			<site name="1_block_l_rtgt_site0" pos="0 0.02 0.02" size="0.01 0.01 0.01" rgba="1 0 0 1" type="sphere" group="1"/>			
      			<site name="left-mid,0,180,conn_site1" pos="0. 0. -0.03" quat="1 0 0 0" rgba="0.9019 0.0980 0.2941 0.3" size="0.01"/>			
      			<site name="left-right,0,180,conn_site2" pos="0. 0. 0.03" quat="1 0 0 0" rgba="0.9019 0.0980 0.2941 0.3" size="0.01"/>			
      			<site name="1_block_l_bottom_site" pos="0.0 0.0 -0.03" rgba="0 0 1 0.3" size="0.0015"/>			
      			<site name="1_block_l_top_site" pos="0.0 0.0 0.03" rgba="0 0 1 0.3" size="0.0015"/>			
      			<site name="1_block_l_horizontal_radius_site" pos="0. 0. 0." rgba="0 0 1 0." size="0.05"/>			
    			<site pos="0 0 0" size="0.002 0.002 0.002" rgba="1 0 0 0" type="sphere" name="1_block_l"/>			<joint name="1_block_l" type="free" damping="0.0001"/>		</body>		
    		<body pos="0.0 0.0 0.09" quat="1 0 0 0" name="2_block_m">			
      			<geom density="100" material="light-wood" name="2_block_m-0" pos="0 0 0" rgba="0.82 0.71 0.55 1" size="0.05 0.02 0.03" solref="0.001 1" type="box" friction="1 10 0.5"/>			
      			<site name="mid-left,0,180,conn_site1" pos="0. 0. 0.03" quat="1 0 0 0" rgba="0.9019 0.0980 0.2941 0.3" size="0.01"/>			
      			<site name="2_block_m_bottom_site" pos="0.0 0.0 -0.03" rgba="0 0 1 0.3" size="0.0015"/>			
      			<site name="2_block_m_top_site" pos="0.0 0.0 0.03" rgba="0 0 1 0.3" size="0.0015"/>			
      			<site name="2_block_m_horizontal_radius_site" pos="0. 0. 0." rgba="0 0 1 0." size="0.05"/>			
    			<site pos="0 0 0" size="0.002 0.002 0.002" rgba="1 0 0 0" type="sphere" name="2_block_m"/>			<joint name="2_block_m" type="free" damping="0.0001"/>		</body>		
    		<body pos="0.0 0.0 0.15" quat="1 0 0 0" name="3_block_r">			
      			<geom density="100" material="light-wood" name="3_block_r-0" pos="0 0 0" rgba="0.82 0.71 0.55 1" size="0.05 0.02 0.03" solref="0.001 1" type="box" friction="1 10 0.5"/>			
      			<site name="3_block_r_ltgt_site0" pos="0 -0.02 0.02" size="0.01 0.01 0.01" rgba="1 0 0 1" type="sphere" group="1"/>			
      			<site name="3_block_r_rtgt_site0" pos="0 0.02 0.02" size="0.01 0.01 0.01" rgba="1 0 0 1" type="sphere" group="1"/>			
      			<site name="right-left,0,180,conn_site1" pos="0. 0. -0.03" quat="1 0 0 0" rgba="0.9019 0.0980 0.2941 0.3" size="0.01"/>			
      			<site name="3_block_r_bottom_site" pos="0.0 0.0 -0.03" rgba="0 0 1 0.3" size="0.0015"/>			
      			<site name="3_block_r_top_site" pos="0.0 0.0 0.03" rgba="0 0 1 0.3" size="0.0015"/>			
      			<site name="3_block_r_horizontal_radius_site" pos="0. 0. 0." rgba="0 0 1 0." size="0.05"/>			
    			<site pos="0 0 0" size="0.002 0.002 0.002" rgba="1 0 0 0" type="sphere" name="3_block_r"/>			<joint name="3_block_r" type="free" damping="0.0001"/>		</body>		
  	</worldbody>	

  	<equality>		
  		<weld active="false" body1="1_block_l" body2="2_block_m" solimp="1 1 0.5" solref="0.01 0.3"/>		
    		<weld active="false" body1="1_block_l" body2="3_block_r" solimp="1 1 0.5" solref="0.01 0.3"/>		
  	</equality>	
	<sensor>		<force name="force_ee" site="ft_frame"/>		
        		<torque name="torque_ee" site="ft_frame"/>		
    	</sensor>	<contact/>	<default/></mujoco>