<?xml version="1.0" ?>
<!-- =================================================================================== -->
<!-- |    This document was autogenerated by xacro from jaco_description/robots/standalone_arm.urdf.xacro | -->
<!-- |    EDITING THIS FILE BY HAND IS NOT RECOMMENDED                                 | -->
<!-- =================================================================================== -->
<robot name="jaco" xmlns:body="http://playerstage.sourceforge.net/gazebo/xmlschema/#body" xmlns:controller="http://playerstage.sourceforge.net/gazebo/xmlschema/#controller" xmlns:gazebo="http://playerstage.sourceforge.net/gazebo/xmlschema/#gz" xmlns:geom="http://playerstage.sourceforge.net/gazebo/xmlschema/#geom" xmlns:interface="http://playerstage.sourceforge.net/gazebo/xmlschema/#interface" xmlns:joint="http://playerstage.sourceforge.net/gazebo/xmlschema/#joint" xmlns:model="http://playerstage.sourceforge.net/gazebo/xmlschema/#model" xmlns:physics="http://playerstage.sourceforge.net/gazebo/xmlschema/#physics" xmlns:renderable="http://playerstage.sourceforge.net/gazebo/xmlschema/#renderable" xmlns:rendering="http://playerstage.sourceforge.net/gazebo/xmlschema/#rendering" xmlns:sensor="http://playerstage.sourceforge.net/gazebo/xmlschema/#sensor" xmlns:xacro="http://ros.org/wiki/xacro" xmlns:xi="http://www.w3.org/2001/XInclude">
    <mujoco>
        <compiler meshdir="../meshes/"/>
    </mujoco>
  <link name="jaco_link_base">
    <inertial>
      <mass value="1.0"/>
      <inertia ixx="0.1" ixy="0" ixz="0" iyy="0.1" iyz="0" izz="0.1"/>
      <origin/>
    </inertial>
    <visual>
      <geometry>
        <mesh filename="package://jaco_description/meshes/jaco_link_base.min.dae" scale="0.0254 0.0254 0.0254"/>
      </geometry>
      <material name="carbon_fiber">
        <color rgba="0.792156862745098 0.819607843137255 0.933333333333333 1"/>
      </material>
    </visual>
    <collision>
      <geometry>
        <mesh filename="package://jaco_description/meshes/jaco_link_base.stl" scale="0.0254 0.0254 0.0254"/>
      </geometry>
    </collision>
  </link>
  <link name="jaco_link_1">
    <inertial>
      <mass value="1.0"/>
      <inertia ixx="0.1" ixy="0" ixz="0" iyy="0.1" iyz="0" izz="0.1"/>
      <origin/>
    </inertial>
    <visual>
      <geometry>
        <mesh filename="package://jaco_description/meshes/jaco_link_1.min.dae" scale="0.0254 0.0254 0.0254"/>
      </geometry>
      <material name="carbon_fiber">
        <color rgba="0.792156862745098 0.819607843137255 0.933333333333333 1"/>
      </material>
    </visual>
    <collision>
      <geometry>
        <mesh filename="package://jaco_description/meshes/jaco_link_1.stl" scale="0.0254 0.0254 0.0254"/>
      </geometry>
    </collision>
  </link>
  <joint name="jaco_joint_1" type="revolute">
    <parent link="jaco_link_base"/>
    <child link="jaco_link_1"/>
    <axis xyz="0 0 1"/>
    <origin rpy="3.141592653589793 0 0" xyz="0 0 0.1535"/>
    <limit effort="30" lower="-6.283185307179586" upper="6.283185307179586" velocity="5"/>
  </joint>
  <link name="jaco_link_2">
    <inertial>
      <mass value="1.0"/>
      <inertia ixx="0.1" ixy="0" ixz="0" iyy="0.1" iyz="0" izz="0.1"/>
      <origin/>
    </inertial>
    <visual>
      <geometry>
        <mesh filename="package://jaco_description/meshes/jaco_link_2.min.dae" scale="0.0254 0.0254 0.0254"/>
      </geometry>
      <material name="carbon_fiber">
        <color rgba="0.792156862745098 0.819607843137255 0.933333333333333 1"/>
      </material>
    </visual>
    <collision>
      <geometry>
        <mesh filename="package://jaco_description/meshes/jaco_link_2.stl" scale="0.0254 0.0254 0.0254"/>
      </geometry>
    </collision>
  </link>
  <joint name="jaco_joint_2" type="revolute">
    <parent link="jaco_link_1"/>
    <child link="jaco_link_2"/>
    <axis xyz="0 0 1"/>
    <origin rpy="-1.5707963267948966 -1.5707963267948966 0" xyz="0 0 -0.1185"/>
    <limit effort="30" lower="0" upper="6.283185307179586" velocity="5"/>
  </joint>
  <link name="jaco_link_3">
    <inertial>
      <mass value="1.0"/>
      <inertia ixx="0.1" ixy="0" ixz="0" iyy="0.1" iyz="0" izz="0.1"/>
      <origin/>
    </inertial>
    <visual>
      <geometry>
        <mesh filename="package://jaco_description/meshes/jaco_link_3.min.dae" scale="0.0254 0.0254 0.0254"/>
      </geometry>
      <material name="carbon_fiber">
        <color rgba="0.792156862745098 0.819607843137255 0.933333333333333 1"/>
      </material>
    </visual>
    <collision>
      <geometry>
        <mesh filename="package://jaco_description/meshes/jaco_link_3.stl" scale="0.0254 0.0254 0.0254"/>
      </geometry>
    </collision>
  </link>
  <joint name="jaco_joint_3" type="revolute">
    <parent link="jaco_link_2"/>
    <child link="jaco_link_3"/>
    <axis xyz="0 0 1"/>
    <origin rpy="3.141592653589793 0 3.141592653589793" xyz="0.41 0 0"/>
    <limit effort="30" lower="0" upper="6.283185307179586" velocity="5"/>
  </joint>
  <link name="jaco_link_4">
    <inertial>
      <mass value="0.5"/>
      <inertia ixx="0.1" ixy="0" ixz="0" iyy="0.1" iyz="0" izz="0.1"/>
      <origin/>
    </inertial>
    <visual>
      <geometry>
        <mesh filename="package://jaco_description/meshes/jaco_link_4_5.min.dae" scale="0.0254 0.0254 0.0254"/>
      </geometry>
      <material name="carbon_fiber">
        <color rgba="0.792156862745098 0.819607843137255 0.933333333333333 1"/>
      </material>
    </visual>
    <collision>
      <geometry>
        <mesh filename="package://jaco_description/meshes/jaco_link_4_5.stl" scale="0.0254 0.0254 0.0254"/>
      </geometry>
    </collision>
  </link>
  <joint name="jaco_joint_4" type="revolute">
    <parent link="jaco_link_3"/>
    <child link="jaco_link_4"/>
    <axis xyz="0 0 1"/>
    <origin rpy="0 -1.5707963267948966 0" xyz="0.207 0 -0.01125"/>
    <limit effort="30" lower="-6.283185307179586" upper="6.283185307179586" velocity="5"/>
  </joint>
  <link name="jaco_link_5">
    <inertial>
      <mass value="0.5"/>
      <inertia ixx="0.1" ixy="0" ixz="0" iyy="0.1" iyz="0" izz="0.1"/>
      <origin/>
    </inertial>
    <visual>
      <geometry>
        <mesh filename="package://jaco_description/meshes/jaco_link_4_5.min.dae" scale="0.0254 0.0254 0.0254"/>
      </geometry>
      <material name="carbon_fiber">
        <color rgba="0.792156862745098 0.819607843137255 0.933333333333333 1"/>
      </material>
    </visual>
    <collision>
      <geometry>
        <mesh filename="package://jaco_description/meshes/jaco_link_4_5.stl" scale="0.0254 0.0254 0.0254"/>
      </geometry>
    </collision>
  </link>
  <joint name="jaco_joint_5" type="revolute">
    <parent link="jaco_link_4"/>
    <child link="jaco_link_5"/>
    <axis xyz="0 0 1"/>
    <origin rpy="0 0.9599310885968813 3.141592653589793" xyz="0.0343 0 -0.06588"/>
    <limit effort="30" lower="-6.283185307179586" upper="6.283185307179586" velocity="5"/>
  </joint>
  <link name="jaco_link_hand">
    <inertial>
      <mass value="1.0"/>
      <inertia ixx="0.1" ixy="0" ixz="0" iyy="0.1" iyz="0" izz="0.1"/>
      <origin/>
    </inertial>
    <visual>
      <geometry>
        <mesh filename="package://jaco_description/meshes/jaco_link_hand.min.dae" scale="0.0254 0.0254 0.0254"/>
      </geometry>
      <material name="carbon_fiber">
        <color rgba="0.792156862745098 0.819607843137255 0.933333333333333 1"/>
      </material>
    </visual>
    <collision>
      <geometry>
        <mesh filename="package://jaco_description/meshes/jaco_link_hand.stl" scale="0.0254 0.0254 0.0254"/>
      </geometry>
    </collision>
  </link>
  <joint name="jaco_joint_6" type="revolute">
    <parent link="jaco_link_5"/>
    <child link="jaco_link_hand"/>
    <axis xyz="0 0 1"/>
    <origin rpy="0 0.9599310885968813 3.141592653589793" xyz="0.0343 0 -0.06588"/>
    <limit effort="30" lower="-6.283185307179586" upper="6.283185307179586" velocity="5"/>
  </joint>
</robot>

